Workbook

Sheet SUMMARY
A1: `
B2: Caaza_Full_Validation_Test_Plan_v1 (All_Platform)
E4: Y____W__
B5: S.NO | C5: Module | D5: No of Test | E5: Executed | F5: PASS | G5: FAIL | H5: NA | I5: NT | K5: S No | L5: Module | M5: Andriod | N5: IOS-Mobile | O5: IOS - Tab | P5: Android - Tab | Q5: Overall %
B6: 1 | C6: Authentication | D6: =Automation!F149 -> #REF! | E6: =Automation!F148 -> #REF! | F6: =Automation!F144 -> #REF! | G6: =Automation!F145 -> #REF! | H6: =Automation!F146 -> #REF! | I6: =Automation!F147 -> #REF! | K6: 1 | L6: Authentication | M6: =(E33/D33) -> 0 | N6: =(E59/D59) -> #REF! | O6: =(E84/D84) -> #REF! | P6: =(E110/D110) -> #REF! | Q6: =(E6/D6) -> #REF!
B7: 2 | C7: Hierarchy_Creation | D7: ='[1] Hierarchy_Creation'!F98 -> #REF! | E7: ='[1] Hierarchy_Creation'!F97 -> #REF! | F7: ='[1] Hierarchy_Creation'!F93 -> #REF! | G7: ='[1] Hierarchy_Creation'!F95 -> #REF! | H7: ='[1] Hierarchy_Creation'!F95 -> #REF! | I7: ='[1] Hierarchy_Creation'!F96 -> #REF! | K7: 2 | L7: Hierarchy_Creation | M7: =(E34/D34) -> #REF! | N7: =(E60/D60) -> #REF! | O7: =(E85/D85) -> #REF! | P7: =(E111/D111) -> #REF! | Q7: =(E7/D7) -> #REF!
B8: 3 | C8: User_Control | D8: =[2]User_Control!F67 -> #REF! | E8: =[2]User_Control!F66 -> #REF! | F8: =[2]User_Control!F62 -> #REF! | G8: =[2]User_Control!F63 -> #REF! | H8: =[2]User_Control!F64 -> #REF! | I8: =[2]User_Control!F65 -> #REF! | K8: 3 | L8: User_Control | M8: =(E35/D35) -> #REF! | N8: =(E61/D61) -> #REF! | O8: =(E86/D86) -> #REF! | P8: =(E112/D112) -> #REF! | Q8: =(E8/D8) -> #REF!
B9: 4 | C9: Home_Page | D9: =[3]Home_Page!F83 -> #REF! | E9: =[3]Home_Page!F82 -> #REF! | F9: =[3]Home_Page!F78 -> #REF! | G9: =[3]Home_Page!F79 -> #REF! | H9: =[3]Home_Page!F80 -> #REF! | I9: =[3]Home_Page!F81 -> #REF! | K9: 4 | L9: Home_Page | M9: =(E36/D36) -> #REF! | N9: =(E62/D62) -> #REF! | O9: =(E87/D87) -> #REF! | P9: =(E113/D113) -> #REF! | Q9: =(E9/D9) -> #REF!
B10: 5 | C10: FlooHierarchy_edit_delete | D10: =[4]FlooHierarchy_edit_delete!F105 -> #REF! | E10: =[4]FlooHierarchy_edit_delete!F104 -> #REF! | F10: =[4]FlooHierarchy_edit_delete!F100 -> #REF! | G10: =[4]FlooHierarchy_edit_delete!F101 -> #REF! | H10: =[4]FlooHierarchy_edit_delete!F102 -> #REF! | I10: =[4]FlooHierarchy_edit_delete!F103 -> #REF! | K10: 5 | L10: FlooHierarchy_edit_delete | M10: =(E37/D37) -> #REF! | N10: =(E63/D63) -> #REF! | O10: =(E88/D88) -> #REF! | P10: =(E114/D114) -> #REF! | Q10: =(E10/D10) -> #REF!
B11: 6 | C11: Add_Switchboard | D11: =[5]Add_Switchboard!E98 -> #REF! | E11: =[5]Add_Switchboard!E97 -> #REF! | F11: =[5]Add_Switchboard!E93 -> #REF! | G11: =[5]Add_Switchboard!E94 -> #REF! | H11: =[5]Add_Switchboard!E95 -> #REF! | I11: =[5]Add_Switchboard!E96 -> #REF! | K11: 6 | L11: Add_Switchboard | M11: =(E38/D38) -> #REF! | N11: =(E64/D64) -> #REF! | O11: =(E89/D89) -> #REF! | P11: =(E115/D115) -> #REF! | Q11: =(E11/D11) -> #REF!
B12: 7 | C12: Connectivity | D12: =[6]Connectivity!G116 -> #REF! | E12: =[6]Connectivity!G115 -> #REF! | F12: =[6]Connectivity!G111 -> #REF! | G12: =[6]Connectivity!G112 -> #REF! | H12: =[6]Connectivity!G113 -> #REF! | I12: =[6]Connectivity!G114 -> #REF! | K12: 7 | L12: Connectivity | M12: =(E39/D39) -> #REF! | N12: =(E65/D65) -> #REF! | O12: =(E90/D90) -> #REF! | P12: =(E116/D116) -> #REF! | Q12: =(E12/D12) -> #REF!
B13: 8 | C13: Analytics | D13: =[7]Analytics!F204 -> #REF! | E13: =[7]Analytics!F203 -> #REF! | F13: =[7]Analytics!F199 -> #REF! | G13: =[7]Analytics!F200 -> #REF! | H13: =[7]Analytics!F201 -> #REF! | I13: =[7]Analytics!F202 -> #REF! | K13: 8 | L13: Analytics | M13: =(E40/D40) -> #REF! | N13: =(E66/D66) -> #REF! | O13: =(E91/D91) -> #REF! | P13: =(E117/D117) -> #REF! | Q13: =(E13/D13) -> #REF!
B14: 9 | C14: Setting & Profile | D14: ='[8]Setting & Profile'!F150 -> #REF! | E14: ='[8]Setting & Profile'!F149 -> #REF! | F14: ='[8]Setting & Profile'!F145 -> #REF! | G14: ='[8]Setting & Profile'!F146 -> #REF! | H14: ='[8]Setting & Profile'!F147 -> #REF! | I14: ='[8]Setting & Profile'!F148 -> #REF! | K14: 9 | L14: Setting & Profile | M14: =(E41/D41) -> #REF! | N14: =(E67/D67) -> #REF! | O14: =(E92/D92) -> #REF! | P14: =(E118/D118) -> #REF! | Q14: =(E14/D14) -> #REF!
B15: 10 | C15: Notification | D15: =[9]Notification!F112 -> #REF! | E15: =[9]Notification!F111 -> #REF! | F15: =[9]Notification!F107 -> #REF! | G15: =[9]Notification!F108 -> #REF! | H15: =[9]Notification!F109 -> #REF! | I15: =[9]Notification!F110 -> #REF! | K15: 10 | L15: Notification | M15: =(E42/D42) -> #REF! | N15: =(E68/D68) -> #REF! | O15: =(E93/D93) -> #REF! | P15: =(E119/D119) -> #REF! | Q15: =(E15/D15) -> #REF!
B16: 11 | C16: Pairing | D16: =[10]Pairing!E194 -> #REF! | E16: =[10]Pairing!E193 -> #REF! | F16: =[10]Pairing!E189 -> #REF! | G16: =[10]Pairing!E190 -> #REF! | H16: =[10]Pairing!E191 -> #REF! | I16: =[10]Pairing!E192 -> #REF! | K16: 11 | L16: Pairing | M16: =(E43/D43) -> #REF! | N16: =(E69/D69) -> #REF! | O16: =(E94/D94) -> #REF! | P16: =(E120/D120) -> #REF! | Q16: =(E16/D16) -> #REF!
B17: 12 | C17: Scheduler | D17: =[11]Scheduler!G125 -> #REF! | E17: =[11]Scheduler!G124 -> #REF! | F17: =[11]Scheduler!G120 -> #REF! | G17: =[11]Scheduler!G121 -> #REF! | H17: =[11]Scheduler!G122 -> #REF! | I17: =[11]Scheduler!G123 -> #REF! | K17: 12 | L17: Scheduler | M17: =(E44/D44) -> #REF! | N17: =(E70/D70) -> #REF! | O17: =(E95/D95) -> #REF! | P17: =(E121/D121) -> #REF! | Q17: =(E17/D17) -> #REF!
B18: 13 | C18: Smart_Scene_Creation | D18: =[12]Smart_Scene_Creation!F70 -> #REF! | E18: =[12]Smart_Scene_Creation!F69 -> #REF! | F18: =[12]Smart_Scene_Creation!F65 -> #REF! | G18: =[12]Smart_Scene_Creation!F66 -> #REF! | H18: =[12]Smart_Scene_Creation!F67 -> #REF! | I18: =[12]Smart_Scene_Creation!F68 -> #REF! | K18: 13 | L18: Smart_Scene_Creation | M18: =(E45/D45) -> #REF! | N18: =(E71/D71) -> #REF! | O18: =(E96/D96) -> #REF! | P18: =(E122/D122) -> #DIV/0!
B19: 14 | C19: Device_Settings | D19: =[13]Device_Settings_Duplicate!F114 -> #REF! | E19: =[13]Device_Settings_Duplicate!F113 -> #REF! | F19: =[13]Device_Settings_Duplicate!F109 -> #REF! | G19: =[13]Device_Settings_Duplicate!F110 -> #REF! | H19: =[13]Device_Settings_Duplicate!F111 -> #REF! | I19: =[13]Device_Settings_Duplicate!F112 -> #REF! | K19: 14 | L19: Device_Settings | M19: =(E46/D46) -> #REF! | N19: =(E72/D72) -> #REF! | O19: =(E97/D97) -> #REF! | P19: =(E123/D123) -> #REF! | Q19: =(E19/D19) -> #REF!
B20: 15 | C20: Multi_device | D20: =[14]Multi_Device!G150 -> #REF! | E20: =[14]Multi_Device!G149 -> #REF! | F20: =[14]Multi_Device!G145 -> #REF! | G20: =[14]Multi_Device!G146 -> #REF! | H20: =[14]Multi_Device!G147 -> #REF! | I20: =[14]Multi_Device!G148 -> #REF! | K20: 15 | L20: Multi_device | M20: =(E47/D47) -> #REF! | N20: =(E73/D73) -> #REF! | O20: =(E98/D98) -> #REF! | P20: =(E124/D124) -> #REF! | Q20: =(E20/D20) -> #REF!
B21: 16 | C21: Switch_ON/OFF | D21: =[15]OFF!F89 -> #REF! | E21: =[15]OFF!F88 -> #REF! | F21: =[15]OFF!F84 -> #REF! | G21: =[15]OFF!F85 -> #REF! | H21: =[15]OFF!F86 -> #REF! | I21: =[15]OFF!F87 -> #REF! | K21: 16 | L21: Switch_ON/OFF | M21: =(E48/D48) -> #DIV/0! | N21: =(E74/D74) -> #DIV/0! | O21: =(E99/D99) -> #DIV/0! | P21: =(E125/D125) -> #DIV/0! | Q21: =(E21/D21) -> #REF!
C22: TOTAL | D22: =SUM(D6:D21) -> #REF! | E22: =SUM(E6:E21) -> #REF! | F22: =SUM(F6:F21) -> #REF! | G22: =SUM(G6:G21) -> #REF! | H22: =SUM(H6:H21) -> #REF! | I22: =SUM(I6:I21) -> #REF!
N23: Overall Completion % | Q23: =(E22/D22) -> #REF!
C24: Issue Tracking Page
B29: Caaza_Full_Validation_Test_Plan_v1 (ANDRIOD)
E31: Y____W__
B32: S.NO | C32: PAIRING MODE | D32: No of Test | E32: Executed | F32: PASS | G32: FAIL | H32: NA | I32: NT
B33: 1 | C33: Authentication | D33: =Automation!F117 -> 97 | E33: =Automation!F116 -> 0 | F33: =Automation!F112 -> 0 | G33: =Automation!F113 -> 0 | H33: =Automation!F114 -> 0 | I33: =Automation!F115 -> 97
B34: 2 | C34: Hierarchy_Creation | D34: ='[1] Hierarchy_Creation'!F66 -> #REF! | E34: ='[1] Hierarchy_Creation'!F65 -> #REF! | F34: ='[1] Hierarchy_Creation'!F61 -> #REF! | G34: ='[1] Hierarchy_Creation'!F62 -> #REF! | H34: ='[1] Hierarchy_Creation'!F63 -> #REF! | I34: ='[1] Hierarchy_Creation'!F64 -> #REF!
B35: 3 | C35: User_Control | D35: =[2]User_Control!F35 -> #REF! | E35: =[2]User_Control!F34 -> #REF! | F35: =[2]User_Control!F30 -> #REF! | G35: =[2]User_Control!F31 -> #REF! | H35: =[2]User_Control!F32 -> #REF! | I35: =[2]User_Control!F33 -> #REF!
B36: 4 | C36: Home_Page | D36: =[3]Home_Page!F50 -> #REF! | E36: =[3]Home_Page!F49 -> #REF! | F36: =[3]Home_Page!F45 -> #REF! | G36: =[3]Home_Page!F46 -> #REF! | H36: =[3]Home_Page!F47 -> #REF! | I36: =[3]Home_Page!F48 -> #REF!
B37: 5 | C37: FlooHierarchy_edit_delete | D37: =[4]FlooHierarchy_edit_delete!F73 -> #REF! | E37: =[4]FlooHierarchy_edit_delete!F72 -> #REF! | F37: =[4]FlooHierarchy_edit_delete!F68 -> #REF! | G37: =[4]FlooHierarchy_edit_delete!F69 -> #REF! | H37: =[4]FlooHierarchy_edit_delete!F70 -> #REF! | I37: =[4]FlooHierarchy_edit_delete!F71 -> #REF!
B38: 6 | C38: Add_Switchboard | D38: =[5]Add_Switchboard!E65 -> #REF! | E38: =[5]Add_Switchboard!E64 -> #REF! | F38: =[5]Add_Switchboard!E60 -> #REF! | G38: =[5]Add_Switchboard!E61 -> #REF! | H38: =[5]Add_Switchboard!E62 -> #REF! | I38: =[5]Add_Switchboard!E63 -> #REF!
B39: 7 | C39: Connectivity | D39: =[6]Connectivity!G91 -> #REF! | E39: =[6]Connectivity!G90 -> #REF! | F39: =[6]Connectivity!G86 -> #REF! | G39: =[6]Connectivity!G87 -> #REF! | H39: =[6]Connectivity!G88 -> #REF! | I39: =[6]Connectivity!G89 -> #REF!
B40: 8 | C40: Analytics | D40: =[7]Analytics!F177 -> #REF! | E40: =[7]Analytics!F176 -> #REF! | F40: =[7]Analytics!F174 -> #REF! | G40: =[7]Analytics!F175 -> #REF! | H40: =[7]Analytics!F176 -> #REF! | I40: =[7]Analytics!F177 -> #REF!
B41: 9 | C41: Setting & Profile | D41: ='[8]Setting & Profile'!F118 -> #REF! | E41: ='[8]Setting & Profile'!F117 -> #REF! | F41: ='[8]Setting & Profile'!F113 -> #REF! | G41: ='[8]Setting & Profile'!F114 -> #REF! | H41: ='[8]Setting & Profile'!F115 -> #REF! | I41: ='[8]Setting & Profile'!F116 -> #REF!
B42: 10 | C42: Notification | D42: =[9]Notification!F88 -> #REF! | E42: =[9]Notification!F87 -> #REF! | F42: =[9]Notification!F83 -> #REF! | G42: =[9]Notification!F84 -> #REF! | H42: =[9]Notification!F83 -> #REF! | I42: =[9]Notification!F84 -> #REF!
B43: 11 | C43: Pairing | D43: =[10]Pairing!E169 -> #REF! | E43: =[10]Pairing!E168 -> #REF! | F43: =[10]Pairing!E164 -> #REF! | G43: =[10]Pairing!E165 -> #REF! | H43: =[10]Pairing!E166 -> #REF! | I43: =[10]Pairing!E167 -> #REF!
B44: 12 | C44: Scheduler | D44: =[11]Scheduler!G100 -> #REF! | E44: =[11]Scheduler!G99 -> #REF! | F44: =[11]Scheduler!G95 -> #REF! | G44: =[11]Scheduler!G96 -> #REF! | H44: =[11]Scheduler!G97 -> #REF! | I44: =[11]Scheduler!G98 -> #REF!
B45: 13 | C45: Smart_Scene_Creation | D45: =[16]Device_Settings!G205 -> #REF! | E45: =[16]Device_Settings!G204 -> #REF! | F45: =[16]Device_Settings!G200 -> #REF! | G45: =[16]Device_Settings!G201 -> #REF! | H45: =[16]Device_Settings!G202 -> #REF! | I45: =[16]Device_Settings!G203 -> #REF!
B46: 14 | C46: Device_Settings | D46: =[14]Multi_Device!G126 -> #REF! | E46: =[14]Multi_Device!G125 -> #REF! | F46: =[14]Multi_Device!G121 -> #REF! | G46: =[14]Multi_Device!G122 -> #REF! | H46: =[14]Multi_Device!G123 -> #REF! | I46: =[14]Multi_Device!G124 -> #REF!
...

Sheet Automation
A1: m | D1: Page Consolidation
B3: TC NO | C3: AUTOMATION_TC_NAME | D3: MODE/MODULE | E3: DESCRIPTION | F3: STEPS TO FOLLOW | G3: Automation Status | H3: EXPECTED BEHAVIOUR | I3: PRIORITY | J3: status | K3: COMMENTS | L3: Used | M3: Android version | N3: Device Serial No | O3: VALIDATED_BY
B4: AUT_TC_NO_01 | C4: TC_02_SignIn_check | D4: Login Functional Check | E4: Check User able to login with Valid creditials | F4: 1. Open innomate app. 2. Enter InValid username and Password and check user not getting validation error. 3. Enter valid username and password and check user able to login to homepage | G4: Completed | I4: P0 | J4: NT
B5: AUT_TC_NO_02 | C5: TC_01_SignUp with Valid creds | D5: Sign Up Functional Check | E5: Check User able to sign up | F5: 1. Open innomate app. 2. Click sign Up Link and check user navigate to Sign Up page 3. Enter valid details and click sign up 4. Enter security answers and check user naviagte to Hierarchy create page | G5: Completed | I5: P0 | J5: NT
B6: AUT_TC_NO_03 | C6: TC_01_SignUp with Valid creds and Create Hierarchy | D6: Sign Up and Create Hierarchy | E6: Sign Up and Create Hierarchy | F6: 1. Open innomate app. 2. Click sign Up Link and check user navigate to Sign Up page 3. Enter valid details and click sign up 4. Enter security answers and check user naviagte to Hierarchy create page 5. Create 4 Level Hierarchy title and check user naviagte to home page 6. Create a 4 Level hierarchy level 7. Check user able to access created Hierarchy | G6: Completed | I6: P0 | J6: NT
B7: AUT_TC_NO_04 | C7: TC_04_removeswitchboard | D7: Pairing | E7: Check user able to Pair with single Device | F7: 1. Login into Innomate app. 2. Pair single node device. 3. Check Connectivy established. 4. Turn on/off. 5. Remove the device | G7: Completed | I7: P0 | J7: NT
B8: AUT_TC_NO_05 | C8: TC05_MultipleSchedule_Timer | D8: Schedule | E8: Check user switch Schedule works | F8: 1. Login into Innomate app. 2. Pair single node device. 3. Create 2 schedule with 2 mins each. 4. Check Schedule hits 5. Check analytics updated properly. | G8: Completed | I8: P0 | J8: NT
B9: AUT_TC_NO_06 | C9: TC_06_SceneCreation | D9: Scene Creation | E9: Check scene creation works | F9: 1. Login into Innomate app. 2. Pair single node device. 3. Check Connectivy established. 4. Turn on/off. 5. Naviagte to home page and create scene. 6. Check scene triggers and switch turn on as per scene. | G9: Completed | I9: P0 | J9: NT
B10: AUT_TC_NO_07 | D10: Edit switchBoardName/Switch Name | E10: Check user able to change Switch Board and switch name | F10: 1. Navigate to switch board page and user able to edit switch board name 2. Check changed name is reflecting in UI. 3. Change the switch name and check changed name is reflecting in UI. | G10: Completed | I10: P0
B11: AUT_TC_NO_08 | C11: TC_07_Device settings | D11: Device Settings | E11: check device setings High voltage values configuration | F11: 1. Login into Innomate app. 2. Pair single node device. 3. Check Connectivy established. 4. Navigate to Device settings page . 5.Navigate to High voltage cutoff 6.validate the high coltage threshold (v) | G11: Completed | I11: P0 | J11: NT
B12: AUT_TC_NO_09 | D12: Device Settings | E12: check device setings low voltage values configuration | F12: 1. Login into Innomate app. 2. Pair single node device. 3. Check Connectivy established. 4. Navigate to Device settings page . 5.Navigate to Low voltage cutoff 6.Validate the Low voltage threshold (v) | G12: Completed | I12: P0
B13: AUT_TC_NO_10 | C13: TC08_Profilepage | D13: Profile | E13: Check user able to update Profile details | F13: 1. Gointo profile section. 2. Check user able edit name,DOB and chane password. 3. Logout and login with new password and check user details updated properly. | G13: Completed | I13: P0 | J13: NT
B14: AUT_TC_NO_11 | C14: TC09_Multiuser | D14: User sharing | E14: Check user able to provide and revoke access to other user | F14: 1. Login into innomate app. 2. Click on users section and click share option. 3. Provide full access to user. 4. Check user got full access. 5. Revoke access to that user. 6. Check user revoke access. | G14: Completed | J14: NT
B15: AUT_TC_NO_12 | D15: User sharing | E15: Check Full access user able to control devices | F15: 1. Check Shared user able to access switch board. 2. Check user able to turn/off switch. 3. Create scehdule in shared user and check created schdule reflects in other user section main user. 4. Schdule triggers properly. | G15: Completed | I15: P0
B16: AUT_TC_NO_13 | D16: User sharing | E16: Check Partial access user able to control devices and not able to create schedule | F16: 1. Check Shared user able to access switch board. 2. Check user able to turn/off switch. 3. Check user not able to Create scehdule in shared user. | G16: Completed | I16: P0
B17: AUT_TC_NO_14 | D17: User sharing | E17: Check view only access user only have access view switch | F17: 1. Check Shared user able to access switch board. 2. Check user not able to turn/off switch. 3. Check user not able to Create scehdule in shared user. | G17: Completed | I17: P0
B18: AUT_TC_NO_15 | C18: TC10_SwitchLock_&_notifications | D18: Check Timer is working for Switch | E18: Check timer is working for switch | F18: 1. Navigate to Switch page and set a timer for 2 mins. 2. Turn the switch and check switch automatically turns off after 2 mins. | G18: Completed | I18: P0 | J18: NT
B19: AUT_TC_NO_16 | D19: Check switch lock Works | E19: Check switch lock works | F19: 1. Navigate to Switch page and enable switch lock 2. Check Switch lock symbol is enabled in Ui and user able to turn on off switch. | G19: Completed | I19: P0
B20: AUT_TC_NO_17 | D20: Check notifications | E20: Check User/Device notification received. | F20: 1. Login to innomate app. 2. Share user to new user. 3, Check user notifications received. 4. Do a factoty reset on current device and device notifications received. | G20: Completed | I20: P0
I21: P0 | J21: NT
I22: P0 | J22: NT
I23: P0 | J23: NT
I24: P0 | J24: NT
I25: P0 | J25: NT
I26: P0 | J26: NT
I27: P0 | J27: NT
I28: P0 | J28: NT
I29: P0 | J29: NT
I30: P0 | J30: NT
I31: P0 | J31: NT
I32: P0 | J32: NT
... I40: P0 | J40: NT
J41: NT
I42: P0 | J42: NT
I43: P0 | J43: NT | K43: https://192.168.10.128:81/issues/15913
I44: P0 | J44: NT
I45: P0 | J45: NT
J46: NT | K46: https://192.168.10.128:81/issues/15915
I47: P0 | J47: NT
I48: P0 | J48: NT
...

Sheet Forget_Page
A1: Summary!A1 | C1: Page Consolidation
B2: TC NO | C2: MODE/MODULE | D2: DESCRIPTION | E2: STEPS TO FOLLOW | F2: EXPECTED BEHAVIOUR | G2: PRIORITY | H2: Android | I2: IOS | J2: Tab | K2: COMMENTS | L2: Used | M2: Android version | N2: Device Serial No | O2: VALIDATED_BY
B3: Forgot_Password TC_NO_01 | C3: Forgot_password Page | D3: Forgot_password UI | E3: 1.Verify alignment and spacing. 2.Check placeholder inside username input. 3.Look for icon in username field. 4.View the Submit button. 5Check “Back to Sign In” link. 6.View “Forgot Password” title. | F3: 1.All elements (title, input, button, links) should be properly aligned and evenly spaced. 2.Placeholder should be "Username" with a red asterisk for mandatory. 3.Username icon should be clearly visible inside the input. 4.Button should be clearly labeled, have proper padding and background color. 5.Should be properly aligned below the Submit button and colored differently (indicating a link). 6.Should be bold and clearly distinguishable from other text. | G3: P0 | H3: NT | I3: NT | J3: NT
B4: Forgot_Password TC_NO_02 | C4: Forgot_password Page | D4: Forgot_password Functional Valid | E4: 1.Enter a valid username and click Submit. 2.Leave the username field empty and click Submit. 3.Click on “Back to Sign In” link. 4.Enter a valid username and click Submit. | F4: 1.Password reset process should initiate or show confirmation. 2.Error message should appear indicating username is required. 3.Should redirect the user to the Sign-In screen. 4.User navigate to Security Question Page without any Issue. | G4: P1 | H4: NT | I4: NT | J4: NT
B5: Forgot_Password TC_NO_03 | C5: Forgot_password Page | D5: Forgot_password Functional Invalid | E5: 1.Enter an invalid or non-registered username and click Submit. 2.Try entering special characters or invalid inputs. 3.Click the Submit button multiple times quickly. | F5: 1.Proper error/validation message should appear (e.g., “Username not found”). 2.Should restrict or show validation if not allowed. 3.Button should either disable after first click or prevent multiple requests. | G5: P2 | H5: NT | I5: NT | J5: NT
B6: Forgot_Password TC_NO_04 | C6: Security_Question Page | D6: Security_Question UI | E6: 1.Check text at the top of the screen. 2.Inspect question labels. 3.Check the placeholder inside both input fields. 4.Check the appearance of the Verify button. | F6: 1.Title should read "Security Question" and be clearly visible. 2.Each question should be numbered and clearly stated. 3.Should show "Your answer" in a readable gray font. 4.Button should be centered, have consistent padding, and readable label. | G6: P3 | H6: NT | I6: NT | J6: NT
B7: Forgot_Password TC_NO_05 | C7: Security_Question Page | D7: Security_Question Functional Valid | E7: 1.Enter valid answers for both questions and click Verify. 2.Enter an answer for only one question and click Verify 3.Leave both fields blank and click Verify. 4.Click on “Back to Sign In”. 5.Use Tab to move between fields and button. 6.Paste an answer in both fields. | F7: 1.Should proceed to the next step (e.g., password reset screen). 2.Should show error message prompting to fill both answers. 3.Should show validation error (e.g., “Both fields are required”). 4.Should redirect user to the login/sign-in page. 5.Keyboard focus should move correctly and allow full interaction. 6.Pasting should be allowed and accepted as input. | G7: P4 | H7: NT | I7: NT | J7: NT
B8: Forgot_Password TC_NO_06 | C8: Security_Question Page | D8: Security_Question Functional InValid | E8: 1.Enter symbols like !@#$%^&* in both fields. 2.Input 1-2 characters (e.g., "A", "XY"). 3.Input numbers (e.g., 123456) in both fields. 4.Enter incorrect answers multiple times. 5.Input spaces (e.g., " ") and submit. | F8: 1.Should either show validation or treat as incorrect answer. 2.Should show validation if there's a minimum length requirement. 3.Should display error if the answers do not match expected format. 4.Should show a warning after a set number of failed attempts (if implemented). 5.Should display error as input is considered empty. | G8: P5 | H8: NT | I8: NT | J8: NT
B9: Forgot_Password TC_NO_07 | C9: Reset_password Page | D9: Reset_password UI | E9: 1.Check title at the top. 2.Inspect both input fields. 3.Check the eye icon. 4.Look at the Continue button. 5.Check “Back to Sign In” link. 6.Visually inspect the fields. 7.Check all text for font consistency. | F9: 1.Title should display "Reset Password" clearly and prominently. 2.Labels should be "New Password" and "Confirm Password", with lock icons and visibility toggle. 3.Clicking the eye icon should toggle password visibility. 4.Button should be centered, visually distinct, and properly styled. 5.Should be readable and clearly placed below the button. 6.All elements should be aligned, evenly spaced, and responsive. 7.Fonts, size, and colors should be uniform and accessible. | G9: P6 | H9: NT | I9: NT | J9: NT
B10: Forgot_Password TC_NO_08 | C10: Reset_password Page | D10: Reset_password Functional Valid | E10: 1.Enter matching, valid new password and confirmation. 2.Click the eye icon in password fields. 3.Click on “Back to Sign In”. 4.Enter different values in both fields. 5.Fill both fields and press Enter. 6.Enter long password (e.g., > 100 chars). 7.Leave one or both fields empty and click Continue. 8. Enter New Password and Confirm password same and click on Continue button, user should get success message. 9. Try login with new password and check User is naviagted to home page. | F10: 1.Should proceed successfully with confirmation or redirection. 2.Should show/hide password characters as expected. 3.Should navigate user to the login screen. 4.Should display error message (e.g., "Passwords do not match") 4.Form should submit successfully as if clicking the Continue button. 6.Field should restrict to allowed max length or give error. 7.Should display required field error(s). 8. Enter New Password and Confirm password same and click on Continue button, user should get success message. 9. Try login with new password and User should naviagte to home page. | G10: P7 | H10: NT | I10: NT | J10: NT
B11: Forgot_Password TC_NO_09 | C11: Reset_password Page | D11: Reset_password Functional InValid | E11: 1.Enter different values in "New Password" and "Confirm Password". 2.Enter weak password (e.g., "1234" or "abcd"). 3.Enter only spaces in password fields. 4.Enter only symbols (e.g., @#$%). 5.Leave both fields empty and click Continue. 6.Enter a password that matches the old one (if known). 7.Enter fewer than required characters (e.g., < 6) | F11: 1.Show validation: "Passwords do not match". 2.Show error or warning: "Password too weak". 3.Show validation error: "Password cannot be blank or whitespace only". 4.Validate against password policy and show appropriate error. 5.Display "Password is required" for both fields. 6.Should show: "New password must be different from old password" (if implemented). 7.Should display error: "Password must be at least X characters". | G11: P8 | H11: NT | I11: NT | J11: NT
E13: Andriod
E14: PASS | F14: =COUNTIF(H3:H11,E14) -> 0
E15: FAIL | F15: =COUNTIF(H3:H11,E15) -> 0
E16: NA | F16: =COUNTIF(H3:H11,E16) -> 0
E17: NT | F17: =COUNTIF(H3:H11,E17) -> 9
E18: Executed | F18: =SUM(F14:F16) -> 0
E19: Total | F19: =SUM(F14:F17) -> 9
E21: IOS_Safari
E22: PASS | F22: =COUNTIF(I3:I11,E22) -> 0
E23: FAIL | F23: =COUNTIF(I3:I11,E23) -> 0
E24: NA | F24: =COUNTIF(H3:H11,E24) -> 0
E25: NT | F25: =COUNTIF(I3:I11,E25) -> 9
E26: Executed | F26: =SUM(F22:F24) -> 0
E27: Total | F27: =SUM(F22:F25) -> 9
E29: TAB_Safari
E30: PASS | F30: =COUNTIF(J3:J11,E30) -> 0
E31: FAIL | F31: =COUNTIF(J3:J11,E31) -> 0
E32: NA | F32: =COUNTIF(J3:J11,E32) -> 0
E33: NT | F33: =COUNTIF(J3:J11,E33) -> 9
E34: Executed | F34: =SUM(F30:F32) -> 0
E35: Total | F35: =SUM(F30:F33) -> 9
E37: TOTAL
E38: PASS | F38: =SUM(F14,F22,F30) -> 0
E39: FAIL | F39: =SUM(F15,F23,F31) -> 0
E40: NA | F40: =SUM(F16,F24,F32) -> 0
E41: NT | F41: =SUM(F17,F25,F33) -> 27
E42: Executed | F42: =SUM(F18,F26,F34) -> 0
E43: Total | F43: =SUM(F19,F27,F35) -> 27

Sheet Copy of Add_Switchboard_pras
A2: Summary!A1 | C2: Page Consolidation
B3: TC NO | C3: MODE/MODULE | D3: DESCRIPTION | E3: STEPS TO FOLLOW | F3: EXPECTED BEHAVIOUR | G3: PRIORITY | H3: Android | I3: IOS | J3: Tab | K3: COMMENTS | L3: Used | M3: Android version | N3: Device Serial No | O3: VALIDATED_BY
B4: TC_01 | C4: Add Switch board | D4: Ensure device names with invalid special characters are rejected. | E4: Precondition: - User is on the Add Device page. - Pairing flow is already completed, and user is ready to enter the device name. 1. Navigate to the 'Enter Name of your smart panel' field. 2. Enter a device name containing special characters (e.g., @#%Device). 3. Tap on Save. | F4: 1. System should validate the input. 2. An error message is displayed (e.g., “Special characters are not allowed in panle name”). 3. Device should not be added until corrected. | H4: NT | I4: NT | J4: NT
B5: TC_02 | C5: Add Switch board | D5: Verify that entering a panel name longer than 11 characters shows an error message and prevents pairing. | E5: Preconditions: - Android app is installed and launched. - Device pairing page is accessible. 1. Navigate to the 'Add Switch' page. 2. Enter a Panel name with more than 11 characters. 3. Attempt to complete Save. | F5: 1. Error message is displayed: “Device name cannot exceed 10 characters.” 2. Pairing is not completed until a valid name is entered. | H5: NT | I5: NT | J5: NT
B6: TC_03 | C6: Add Switch board | D6: Ensure device names shorter than 3 characters are rejected. | E6: Preconditions: 1. App is installed and launched. 2. Device pairing page is accessible. 1. Navigate to the device pairing page. 2. Enter a device name with less than 3 characters (e.g., “A”, “AB”). 3. Attempt to complete pairing. | F6: 1. Error message displayed: “Device name must be at least 3 characters.” 2. Pairing is not completed until a valid name is entered. | H6: NT | I6: NT | J6: NT
B7: TC_04 | C7: Add Switch board | D7: Verify numeric-only device names are accepted during pairing. | E7: Preconditions: - Device pairing is in progress. - User is on the Device Name entry screen. 1. Enter a numeric-only device name (e.g., 12345). 2. Tap Save to proceed with pairing. | F7: 1. The numeric name is accepted as valid. 2. Pairing proceeds successfully. 3. Device appears in the device list/dashboard with the numeric name. | H7: NT | I7: NT | J7: NT
B8: TC_05 | C8: Add Switch board | D8: Verify app retains input data when sent to background during entry. | E8: Preconditions: - Device pairing is in progress. - User is on the Device Name or Switch Name & Load Type entry screen. 1. Enter partial or complete device/switch details. 2. Minimize the app (send it to background) without saving. 3. Reopen the app. 4. Navigate back to the entry screen. | F8: 1. All previously entered data remains intact. 2. User can continue pairing without re-entering information. 3. Pairing completes successfully. | H8: NT | I8: NT | J8: NT
B9: TC_06 | C9: Add Switch board | D9: Default device name assignment on app close | E9: Preconditions: - Device pairing is successfully completed. - User is on the Device Name entry screen. 1. When prompted to enter the Panel Name, leave it blank. 2. Kill the app (force close). 3. Reopen the app and check the device list. | F9: 1. The system should automatically assign a default device name (e.g., Device_001 or Switch_board_1). 2. The device should appear in the Home Page/device list with this default name, and all switches should also have unique default names without duplicates (e.g., Switch_1, Switch_2, …). 3. User should be able to later rename both the device and switches from Edit Device Settings. | H9: NT | I9: NT | J9: NT
B10: TC_07 | C10: Add Switch board | D10: Default device name assignment on second panel addition | E10: Preconditions: - First panel is already paired and available in the device list. - User is on the Device Name entry screen while adding a second panel. 1. When prompted to enter the Panel Name for the second panel, leave it blank. 2. Kill the app (force close). 3. Reopen the app and check the device list. | F10: 1. The system should automatically assign a default name to the second panel (e.g., Device_002 or Switch_board_2). 2. Both the first and second panels should appear in the Home Page/device list with unique default names. 3. All switches of the second panel should also have unique default names without duplicates (e.g., Switch_1, Switch_2 …). 4. User should be able to later rename the second panel and its switches from Edit Device Settings. | H10: NT | I10: NT | J10: NT
B11: TC_08 | D11: Ensures back navigation on the Switch Board Name page does not proceed with pairing. | E11: Preconditions: - First panel is already paired and available in the device list. - User is on the Device Name entry screen. 1. Enter the Switch Board Name screen during pairing. 2. Press the mobile back button. | F11: 1. No further action should proceed. 2. User should remain on the Switch Board Name page until a valid name is entered or confirmed. | H11: NT | I11: NT | J11: NT
B12: TC_09 | C12: Add Switch board | D12: Verify switch count for V1 after saving panel name | E12: Preconditions: - V1 panel pairing is successfully completed. - User is on the Panel Name entry screen. 1. Enter a valid panel name (e.g., LivingRoom_V1). 2. Save the panel name. 3. Navigate to the detailed view of the V1 panel. | F12: 1. The V1 panel should display exactly 6 switches after the panel name is saved. | H12: NT | I12: NT | J12: NT
B13: TC_10 | C13: Add Switch board | D13: Verify switch count for V2 Single after saving panel name | E13: Preconditions: - V2 Single panel pairing is successfully completed. - User is on the Panel Name entry screen. 1. Enter a valid panel name (e.g., Bedroom_V2). 2. Save the panel name. 3. Navigate to the detailed view of the V2 Single panel. | F13: 1. The V2 Single panel should display exactly 1 switch after the panel name is saved. | H13: NT | I13: NT | J13: NT
B14: TC_11 | C14: Add Switch board | D14: Verify switch count for V2 Dual after saving panel name | E14: Preconditions: - V2 Dual panel pairing is successfully completed. - User is on the Panel Name entry screen. 1. Enter a valid panel name (e.g., LivingRoom_V2). 2. Save the panel name. 3. Navigate to the detailed view of the V2 Dual panel. | F14: 1. The V2 Dual panel should display exactly 2 switches after the panel name is saved. | H14: NT | I14: NT | J14: NT
B15: TC_12 | C15: Add Switch board | D15: Verify switch name does not accept special characters | E15: Preconditions: - Device is paired and panel is added successfully. - User is on the Switch Name entry/edit screen. 1. Enter a switch name with special characters (e.g., $Light1). 2. Attempt to save the switch name. | F15: 1. The system should reject the name. 2. An error message should be displayed (e.g., “Special characters are not allowed in switch name.”). 3. Switch name should remain editable for correction. | H15: NT | I15: NT | J15: NT
B16: TC_13 | C16: Add Switch board | D16: Verify duplicate switch names are not allowed | E16: Preconditions: - Device is paired and panel name saved. - User is on the Switch Name entry screen. 1. Enter a name for Switch 1 (e.g., Light1). 2. Enter the same name for Switch 2 (e.g., Light1). 3. Attempt to save. | F16: 1. System should reject the duplicate entry. 2. Error message is displayed (e.g., “Switch name must be unique.”). 3. User remains on the naming screen until corrected. | H16: NT | I16: NT | J16: NT
B17: TC_14 | C17: Add Switch board | D17: Verify default switch name is applied when app is Kill mid-entry | E17: Preconditions: - Device is paired Panel name added. - User is on the Switch Name entry screen. 1. On the Switch Name entry screen, leave some or all switch names blank. 2. Force Kill the app without saving. 3. Reopen the app and navigate to the device/switch list. | F17: 1. The saved Panel name should remain unchanged as entered previously. 2. The system should automatically assign default switch names (e.g., Switch_1, Switch_2, …) for any blank entries. 3. The device should appear with all switches listed under these default names. 4. User should be able to later rename switches from Edit Switch Settings. | H17: NT | I17: NT | J17: NT
B18: TC_15 | C18: Add Switch board | D18: Ensures back navigation on the Switch Name page does not proceed. | E18: Preconditions: - Device is paired Panel name added. - User is on the Switch Name entry screen. 1. On the Switch Name input page, press the mobile back button. 2. Observe the app behavior. | F18: 1. No further action or page navigation from Switch Name input to Switch Board Name input popup. 2. User remains on the same page until valid input or navigation is chosen. | H18: NT | I18: NT | J18: NT
B19: TC_16 | C19: Add Switch board | D19: Ensure error is shown if load type is skipped while entering switch names. | E19: Preconditions: - Device is paired and Panel Name has been added. - User is on the Switch Name entry screen. 1. Enter switch names (valid or blank as per case). 2. Do not select any load type for one or more switches. 3. Tap Save. | F19: 1. System should display an error message (e.g., “Please select a load type for all switches”). 2. User should not be allowed to proceed until a load type is assigned to each switch. | H19: NT | I19: NT | J19: NT
B20: TC_17 | C20: Add Switch board | D20: Switch load type Ensures unselected load types default to Socket while device/switch names remain saved. | E20: Preconditions: - Device pairing is completed. - User is on the Switch Name entry screen. 1. On the Switch Name & Load Type screen, leave the load type unselected. 2. Force close the app without saving. 3. Reopen the app and navigate to the same device’s switch list. | F20: 1. The system should automatically assign the default load type as Socket for all switches where no load type was selected, and a corresponding switch image should be displayed for each. 2. Device and switch names should persist as per the previously saved entries. 3. User can later update the load type from Edit Switch Settings. | H20: NT | I20: NT | J20: NT
B21: TC_18 | C21: Add Switch board | D21: Checks input fields and dropdowns are clear, aligned, and responsive. | E21: Preconditions: - Device pairing is completed. - User is on the Switch Name entry screen 1. Check visibility and alignment of input fields and dropdowns. 2. Interact with fields to verify responsiveness. 3. Verify labels and placeholders are readable. | F21: 1. All fields and dropdowns are properly aligned, responsive, and clearly visible. | H21: NT | I21: NT | J21: NT
B22: TC_19 | C22: Add Switch board | D22: Verify device pairing completes within 5s on stable Wi-Fi. | E22: Preconditions: - Device is paired under a stable Wi-Fi connection. 1. Start the device pairing process under stable Wi-Fi. 2. Complete the pairing and setup. 3. Measure response/processing time. | F22: 1. Device addition should be completed within 5 seconds under a stable network. | H22: NT | I22: NT | J22: NT
B23: TC_20 | C23: Add Switch board | D23: Verify device pairing handles weak Wi-Fi by showing retry or error message gracefully. | E23: Preconditions: - Device is ready for pairing. - User’s phone is connected to a weak/unreliable Wi-Fi network. 1. Start device pairing under weak Wi-Fi conditions. 2. Monitor the app response during the pairing process. 3. Check for retry/error prompts if connection fails. | F23: 1. Pairing should not proceed silently. 2. The app should display a retry option or error message gracefully. 3. No app crash or freeze should occur. | H23: NT | I23: NT | J23: NT
... B32: TC_29 | C32: Add Switch board | D32: Verify app handles network loss gracefully during device setup without data loss. | E32: Preconditions: - Device pairing is in progress. - Device is connected to Wi-Fi or mobile data. - User is on the Device Name or Switch Name & Load Type entry screen. 1. Start entering device/switch details and begin pairing. 2. Disconnect Wi-Fi or mobile data mid-setup. 3. Observe app behavior: check for retry prompts, error messages, or automatic reconnection attempts. 4. Reconnect network and continue pairing process. | F32: 1. App displays a clear error or retry message without crashing. 2. Previously entered data is retained. 3. User can resume pairing once the network is restored. | H32: NT | I32: NT | J32: NT
C33: ADD DEVICE NAME IN SWITCHBOARD | D33: Add new switchboard name UI Check | E33: 1.Check Top of the page "Switchboard "Title is centrally present 2.Check Textbox input field present 3.Check Placeholder text present or not . 4.Check UI Layout by Using page on phone, tablet, iPad and Rotate it in landscape/portrait | F33: 1.Top of the page "Switchboard "Title should be present. 2.Textbox field should be present. 3.Placeholder text "Enter your smart panel name" should be present 4.UI adapts, is touch-friendly, no clipping/overflow | H33: NT | I33: NT | J33: NT
C34: ADD DEVICE NAME IN SWITCHBOARD | D34: Add new switchboard name Valid Check | E34: 1.Check Device name accepts valid alpha-numeric input, within limit 2.Verify while entering On device name page,then close app and Reopen app | F34: 1.Device name should be accepted, user proceeds to switch naming 2.Device gets default name (e.g., “MyDevice123”), user must able to edit this later | H34: NT | I34: NT | J34: NT
C35: ADD DEVICE NAME IN SWITCHBOARD | D35: Add new switchboard name InValid Check | E35: 1.Check Device name field with empty input 2.Check Device name as entering special characters (Eg: ‘My@Device!’) 3.Enter name exceeding max length (e.g., 15+ chars) | F35: 1.Error message as “Device name cannot be empty” should appear and Save button should be disabled 2.Error message as “Special characters not allowed” should appear . 3.Error message as “Enter name within 10 Characters” should appear. | H35: NT | I35: NT | J35: NT
B36: Add_Switchboard_TC_76 | C36: EDIT SWITCH BOARD | D36: Edit Switch Board Page UI Check | E36: Pre-Condition : - In Room Page, After Clicking SideBar Menu ,In that after clicking Switchboard Edit it navigates directly to Add Switch Page 1.Check if header, back icon, location breadcrumb, text fields, dropdowns, 3-dot menu, and Save are aligned properly 2.Check placeholder text displaying "pairing time entered switch name" or “Enter Switch Name” is present or not 3.Tap dropdown on any row 4.Observe Save button across all screens | F36: 1.All UI components should be aligned and visible properly on all screens 2.In Placeholder Text, While displaying "Pairing time entered switch name" or “Enter Switch Name” should be present 3.Should display types like “Fan, Light, AC, TV, Other” with proper spacing 4.Save button should be aligned, styled consistently, and inactive until valid input is entered | H36: NT | I36: NT | J36: NT
B37: Add_Switchboard_TC_77 | C37: EDIT SWITCH BOARD | D37: Edit Switch Board Page UI Check | E37: 5.Check After Entering Switch Name, it changes correctly or not . Eg: ( 'Ac' ) 6.Check After Clicking any Fields in the Dropdown, Atlast Selected Specific Field is shown or not 7.Verify After Clicking 3 dots, Edit option is shown or not 8.Check After Clicking Edit Option, It shows Enter Switch Name Page or not | F37: 5.After Entering Switch Name, it should change correctly 6.After Clicking any Fields in the Dropdown, Atlast Selected Specific Field should be shown 7.After Clicking 3 dots, Edit option should be shown 8.After Clicking Edit Option, It should directly show Enter Switch Name Page | H37: NT | I37: NT | J37: NT
B38: Add_Switchboard_TC_78 | C38: EDIT SWITCH BOARD | D38: Edit Switch Board Page Functionality Check | E38: 1.Check Dropdown and its sub section are clickable or not 2.Check 3 dot button and its edit Button is clickable or not 3.Check After Changes Save Button is clickable or not 4.In Enter Switch Name Page , Check User able to enter or not 5. Check App Back button is clickable or not | F38: 1.Dropdown and its sub section should be clickable 2. 3 dot button and its edit Button should be clickable 3. After Changes Save Button should be clickable 4.In Enter Switch Name Page , User should able to enter in the field 5.App Back button should be clickable | H38: NT | I38: NT | J38: NT
B39: Add_Switchboard_TC_79 | C39: EDIT SWITCH BOARD | D39: Edit Switch Board Page Valid Check | E39: 1.Enter unique switch name (e.g., “Fan 1”), select type from dropdown, tap Save (Page 1/2) 2.Enter multiple names + types in available rows eg.(Max 6 switches) 3.Enter new switch name manually | F39: 1.Switch should be added successfully 2.All entered switches should be saved when Save is tapped 3.Field should accept new name and activate Save button | H39: NT | I39: NT | J39: NT
B40: Add_Switchboard_TC_80 | C40: EDIT SWITCH BOARD | D40: Edit Switch Board Page Valid Check | E40: 4.Leave name field blank or unselected type, try to tap Save 5.Enter duplicate switch names 6.Choose “Fan” from type dropdown → keep name field blank → Tap Save | F40: 4.Save button should remain disabled unless all required fields are filled 5.App should prevent duplicate names or display a warning 6.Save button should remain inactive | H40: NT | I40: NT | J40: NT
B41: Add_Switchboard_TC_81 | C41: EDIT SWITCH BOARD | D41: Edit Switch Board Page InValid Check | E41: 1.Add duplicate switch names eg :(Enter “Fan 1” in two different rows → Tap Save) 2.Enter unsupported special characters in name eg :(Enter special characters like @#&%* in switch name field → Tap Save) 3.Complete all required fields → Turn off internet → Tap Save | F41: 1.Should show validation error or prevent submission 2.Should display error or not allow save if unsupported characters are restricted 3.App should show appropriate error or offline handling message | H41: NT | I41: NT | J41: NT
D44: New Test Cases for Device_Add_1 | E44: Raashid
B46: Add Device_1_tc_001 | C46: ADD DEVICE NAME IN SWITCHBOARD | D46: Add new switchboard name Valid Check | E46: 1.Check Device name accepts valid alpha-numeric input, within limit 2.Verify while entering On device name page,then close app and Reopen app | F46: 1.Device name should be accepted, user proceeds to switch naming 2.Device gets default name (e.g., “MyDevice123”), user must able to edit this later | H46: NT | I46: NT | J46: NT
B47: Add Device_1_tc_002 | C47: ADD DEVICE NAME IN SWITCHBOARD | D47: Add new switchboard name InValid Check | E47: 1.Check Device name field with empty input 2.Check Device name as entering special characters (Eg: ‘My@Device!’) 3.Enter name exceeding max length (e.g., 15+ chars) | F47: 1.Error message as “Device name cannot be empty” should appear and Save button should be disabled 2.Error message as “Special characters not allowed” should appear . 3.Error message as “Enter name within 10 Characters” should appear. | H47: NT | I47: NT | J47: NT
B48: Add Device_1_tc_003 | C48: ADD SWITCH PAGE | D48: Add switch Page Valid Check | E48: 1.Check Switch name accepts valid alpha-numeric input (Eg : MainLight) 2.Verify while entering On Switch name,then close app and Reopen app | F48: 1.Field should be accepted. 2.Switch name gets default name (e.g., “Switch 1”), user must able to edit this later | H48: NT | I48: NT | J48: NT
B49: Add Device_1_tc_004 | C49: ADD SWITCH PAGE | D49: Add switch Page InValid Check | E49: 1.Check Switch name as entering special characters (Eg: ‘Fan!@#’) 2.Check entering Input name by exceeding limit | F49: 1.Error message as “Special characters not allowed” should appear . 2.Error or input should be capped. | H49: NT | I49: NT | J49: NT
H50: NT | I50: NT | J50: NT
E51: Varadharajan | H51: NT | I51: NT | J51: NT
B52: Add Device_1_TC_01 | C52: Add_Switchboard | D52: Verify switches display as square cards under room | E52: Pre-Conditions Room has multiple switches paired 1.Navigate to the last hierarchy. 2.Open a room with multiple paired switches. | F52: All switches for that room are displayed as square cards below the “Devices” heading. | H52: NT | I52: NT | J52: NT
...

Sheet Copy of Add_Switchboard_OLD
A2: Summary!A1 | C2: Page Consolidation
B3: TC NO | C3: MODE/MODULE | D3: DESCRIPTION | E3: STEPS TO FOLLOW | F3: EXPECTED BEHAVIOUR | G3: PRIORITY | H3: Android | I3: IOS | J3: Tab | K3: COMMENTS | L3: Used | M3: Android version | N3: Device Serial No | O3: VALIDATED_BY
B4: Add_Switchboard_TC_01 | C4: PAIRING UI | D4: Add device Page | E4: Precondition: navigate to Last page of Hierarchy which used names as XXX and in that Page, checking the app shows Add Switchboard button text as "Add Switchboard " text | F4: APP should display XXX page with Add Switchboard button text as "Add Switchboard " | G4: P0 | H4: NT | I4: NT | J4: NT
E5: Clicking "Add Switchboard " button app navigate the user to "Switch the device into pairing Mode page" | F5: APP should navigate the user to "Switch the device into pairing Mode" page after clicking Add Switchboard button.
B6: Add_Switchboard_TC_02 | C6: PAIRING UI | E6: Precondition:System theme toggled Open pairing and progress screens across states | F6: Colors/contrast adapt; no readability loss; icons/text visible | G6: P0 | H6: NT | I6: NT | J6: NT
E7: Precondition:System font size large Open pairing flows | F7: Layout adapts; no truncation/overlap; buttons tappable
B8: Add_Switchboard_TC_03 | C8: PAIRING UI | D8: Next Page | E8: Verify "Next" button is working only if we enable "Device is in Pairing mode" tick box | F8: If Pairing mode is disabled, Next button should not enabled If Pairing mode is enabled, Next button should enabled | G8: P0 | H8: NT | I8: NT | J8: NT
B9: Add_Switchboard_TC_04 | C9: PAIRING UI | E9: 1.Verify ""Switch the device into Pairing Mode"" content 2.Check the text in Next PAGE button | F9: - Heading should be center & proper format - Body of content should be properly alliged - Note content should be properly alliged - ""Next"" text should be placed in the button | G9: P0 | H9: NT | I9: NT | J9: NT
B10: Add_Switchboard_TC_05 | C10: PAIRING UI | E10: Verify "Device Press" image | F10: - Check "Device Press" hd image included - Check image is not hidden or disappears | G10: P0 | H10: NT | I10: NT | J10: NT
B11: Add_Switchboard_TC_06 | C11: PAIRING UI | E11: Verify "Next" button UI | F11: "Next" icon text should not be hidden "Next" icon should not be in abnormal state | G11: P0 | H11: NT | I11: NT | J11: NT
B12: Add_Switchboard_TC_07 | C12: PAIRING UI | E12: Clicking Next button app navigate the user to "Start Pairing" Page. | F12: APP should navigate the user to "Start Pairing" Page after clicking Next Button . | G12: P0 | H12: NT | I12: NT | J12: NT
B13: Add_Switchboard_TC_08 | C13: PAIRING UI | D13: Start Pairing Page | E13: In Start Pairing Page, Check the page content | F13: ;- Heading should be center & proper format - Body of content should be properly alliged - Note content should be properly alliged - ""Start Pairing"" text should be placed in the button | G13: P0 | H13: NT | I13: NT | J13: NT
B14: Add_Switchboard_TC_09 | C14: PAIRING UI | E14: Verify "Start Pairing" button UI | F14: "Start Pairing" icon text should not be hidden "Start Pairing" icon should not be in Abnormal state | G14: P0 | H14: NT | I14: NT | J14: NT
B15: Add_Switchboard_TC_10 | C15: PAIRING UI | E15: Clicking Start Pairing button app navigate the user to "Pairing page" and shows location permission pop up | F15: APP should navigate the user to "Pairing page" and shows location permission pop up after clicking Start pairing button | G15: P0 | H15: NT | I15: NT | J15: NT
B16: Add_Switchboard_TC_11 | C16: PAIRING UI | D16: Location Permission | E16: While APP asking for location permission in pairing process, give "Don't Allow" to check whether APP shows "Location Services" pop up or not | F16: After giving "Don't Allow", APP should not initiate pairing and show "Location Services" pop-up | H16: NT | I16: NT | J16: NT
B17: Add_Switchboard_TC_12 | C17: PAIRING UI | E17: Now Click "SETTINGS" on "Location Services" pop up and check APP navigate to APP info page and Didn't select any other option go back, app navigate to add device page. | F17: APP navigate to APP info page and Didn't select any other option go back, app navigate to add device page. | H17: NT | I17: NT | J17: NT
B18: Add_Switchboard_TC_13 | C18: PAIRING UI | E18: 1. Go to APP info and provide "Clear all data" 2. Initiate the pairing procedure and provide "DONT ALLOW" during Location permission 3. In "Location Services" pop up, give "cancel" button to check the app behaviour | F18: 1. Clear all data should work 2. Cancel button should work 3. After cancel APP should navigate to "ADD DEVICE" page | H18: NT | I18: NT | J18: NT
B19: Add_Switchboard_TC_14 | C19: PAIRING UI | E19: - Applicable from Android12 version 1. Go to APP info and provide "Clear all data" 2. Initiate the pairing procedure and provide "ONLY THIS TIME" during Location permission | F19: 1. Clear all data should work 2. After giving only this time, app should moves to ask for Nearby device permission | H19: NT | I19: NT | J19: NT
B20: Add_Switchboard_TC_15 | C20: PAIRING UI | E20: - Applicable from Android12 version 1. Within 2mins of above test, close the application and re-open 2. Initiate the pairing procedure and provide "ONLY THIS TIME" during Location permission to check whether paring is initiated or not | F20: 1. After giving only this time, app should moves to ask for Nearby device permission or if Nearby device permission is already given it should proceed to paring, 2. APP should not throw any issue related to location during pairing | H20: NT | I20: NT | J20: NT
B21: Add_Switchboard_TC_16 | C21: PAIRING UI | E21: - Applicable from Android12 version 1. After completion of above test wait for 5mins then close the application and re-open 2. Initiate the pairing procedure and provide "ONLY THIS TIME" during Location permission to check whether paring is initiated or not | F21: 1. After giving only this time, app should ask for Location permission again | H21: NT | I21: NT | J21: NT
B22: Add_Switchboard_TC_17 | C22: PAIRING UI | E22: 1. Initiate the pairing procedure and provide "WHILE USING THE APP" during Location permission to check whether paring is initiated or not | F22: 1. After giving "WHILE USING THE APP", app should moves to ask for Nearby device permission or if Nearby device permission is already given it should proceed to paring, 2. APP should not throw any issue related to location during pairing | H22: NT | I22: NT | J22: NT
B23: Add_Switchboard_TC_18 | C23: PAIRING UI | E23: 1. Give "While Using the APP" permission 2. Close the APP 3. Disable location service using APP INFO 4. Try to initiate pairing procedure 5. Check whether Location disabled error pop-up thrown and APP takes us to setting page to enable location service | F23: 1.After initiating pairing procedure, APP should show location related failure pop-up 2. And takes user to setting page to enable location service | H23: NT | I23: NT | J23: NT
B24: Add_Switchboard_TC_19 | C24: PAIRING UI | E24: 1. Go to APP info and provide "Clear all data" 2. Initiate the pairing procedure and provide "WHILE USING THE APP" during Location permission & select Precise location as OFF 3. After step2, check APP proceed with pairing procedure | F24: 1. Clear all data should work 2. APP should proceed to decrease the pairing count even after giving precise location as OFF 3. APP should not crash or struck at any time | H24: NT | I24: NT | J24: NT
B25: Add_Switchboard_TC_20 | C25: PAIRING UI | D25: Nearby Device Permission | E25: - Applicable from Android11 version 1. Go to APP info and provide "Clear all data" 2. Initiate the pairing procedure and provide "ONLY THIS TIME" during Location permission 3. While APP asking for Nearby Device Permission, give "Don't Allow" and check APP behaviour | F25: After giving "Don't Allow" APP should pop-up the "Allow Bluetooth Connections" | H25: NT | I25: NT | J25: NT
B26: Add_Switchboard_TC_21 | C26: PAIRING UI | E26: Now Click "SETTINGS" on "Allow Bluetooth Connection" pop up and check APP navigate to APP info page and Didn't select any other option go back, app navigate to add device page. | F26: APP navigate to APP info page and Didn't select any other option go back, app navigate to add device page. | H26: NT | I26: NT | J26: NT
B27: Add_Switchboard_TC_22 | C27: PAIRING UI | E27: 1. Go to APP info and provide "Clear all data" 2. Initiate the pairing procedure and provide "While Using this APP" during Location permission 3. While APP asking for Nearby Device Permission, give "Don't Allow" 4. In "Allow Bluetooth Connection" pop-up give "Cancel" button | F27: APP should not throw any error and close the "Allow Bluetooth Connection" pop-up and moves to "ADD DEVICE" page | H27: NT | I27: NT | J27: NT
B28: Add_Switchboard_TC_23 | C28: PAIRING UI | E28: 1. Go to APP info and provide "Clear all data" 2. Initiate the pairing procedure and provide "While Using this APP" during Location permission 3. While APP asking for Nearby Device Permission, give "Allow" to check the APP behaviour | F28: APP should not show Nearby Device permission related failure during Pairing | H28: NT | I28: NT | J28: NT
B29: Add_Switchboard_TC_24 | C29: PAIRING UI | E29: 1. Give Allow access to Nearby Share 2. Close the APP 3. Turn off Bluetooth 4. Re-open the APP 5. Try to initiate pairing procedure | F29: APP should not show any Nearby Device permission related failure during Pairing and ask user to Turn ON the Bluetooth | G29: P0 | H29: NT | I29: NT | J29: NT
B30: Add_Switchboard_TC_25 | C30: PAIRING UI | D30: Ble and Wifi Turn on process | E30: 1. Keep Wi-Fi and BLE turn OFF state in Mobile 2. Open the app and initate the paring procdure to check whether APP shows "allow Caaza to access this device`s location" pop up or not | F30: app should show ""allow CaaZa to access this device`s location" pop up with "allow only while using the app" and "deny" button | G30: P0 | H30: NT | I30: NT | J30: NT
B31: Add_Switchboard_TC_26 | C31: PAIRING UI | E31: 1. Keep Wi-Fi and BLE turn OFF state in Mobile 2. Open the app and initate the paring procdure to check whether APP shows "Turn ON BLE" pop up or not | F31: App should show "Turn ON BLE" pop up" with "OK" and "CANCEL" button's | G31: P0 | H31: NT | I31: NT | J31: NT
B32: Add_Switchboard_TC_27 | C32: PAIRING UI | E32: In "Turn ON BLE" pop up, click on CANCEL to check whether app show "Turn ON WiFi" pop up or not | F32: App should show "Turn ON WiFi" pop-up with "OK" and "CANCEL" button's | G32: P0 | H32: NT | I32: NT | J32: NT
B33: Add_Switchboard_TC_28 | C33: PAIRING UI | E33: In "Turn ON WiFi" pop up, click on CANCEL to check whether pairing cancel and navigate the user to add device page. | F33: APP should navigate the user to add device page and show "To Proceed Pairing Bluetooth or WiFI must be Turned ON" | G33: P0 | H33: NT | I33: NT | J33: NT
B34: Add_Switchboard_TC_29 | C34: PAIRING UI | E34: 1. Keep Wi-Fi and BLE turn OFF state in Mobile 2. Open the app and initate the paring procedure to check whether APP shows "Turn ON BLE" pop up or not 3. In "Turn On BLE" pop up, click on OK to check whether APP shows "Turn ON WiFi" pop up or not | F34: APP should shows "Turn ON WiFi" pop up while after give ok in "Turn On BLE" pop up. | G34: P0 | H34: NT | I34: NT | J34: NT
B35: Add_Switchboard_TC_30 | C35: PAIRING UI | E35: 1. After above test completion, In "Turn On WiFI" pop up, click on OK to check whether APP takes user to WiFi page or not | F35: 1. App should take user to Wi-Fi page, after connected to WiFi 2. Comeback to APP confirm Pairing proceeded or not | G35: P0 | H35: NT | I35: NT | J35: NT
B36: Add_Switchboard_TC_31 | C36: PAIRING UI | D36: Pairing Window - "Pairing process" | E36: 1. Keep Wi-Fi and BLE turn OFF state in Mobile 2. Open the app and initate the paring procdure to check whether APP shows "Turn ON BLE" pop up or not 3. In "Turn On BLE" pop up, click on CANCEL to check whether APP shows "Turn ON WiFi" pop up or not 4. In "Turn ON WiFi" pop up, click on OK to check whether APP takes to WiFi page or not 5. After connecting to WiFI check its proceed to pairing procedure or not | F36: 1. After step4, APP should takes user to WiFi page 2. After connecting to WiFi APP should proceed with pairing procedure (Pairing timer should be running) 3. APP should not struck at any step or show black screen at any time | H36: NT | I36: NT | J36: NT
B37: Add_Switchboard_TC_32 | C37: PAIRING UI | E37: After precondition process, APP show ask for Router password if Wi-Fi is enabled | F37: APP should ask for Router password alert if user connect with router | H37: NT | I37: NT | J37: NT
C38: PAIRING UI | E38: Preconditions:Wrong password or router out of range Enter invalid password OR power off router mid-process | F38: App surfaces clear error reason (auth fail or router unreachable); suggests re-pair; device returns to pairing mode
B39: Add_Switchboard_TC_33 | C39: PAIRING UI | E39: 1. While app shows router credential pop up click back (Mobile back button or swipe) 2. APP should take that back button as cancel and it should not show any other pop-up overlaying current pop-up | F39: APP should cancel the pop up and take the user for pairing process or not to close the current pop up if user click back | H39: NT | I39: NT | J39: NT
B40: Add_Switchboard_TC_34 | C40: PAIRING UI | E40: 1. Check after entering password, "Show Password" option is working or not 2. Check during password enter any background texts are getting overlapped or hidden | F40: 1. If you enable "Show Pasword", password should be visible, if we disable it should not be visible 2. During password enter, background text should be visible all the time and it should not get overlapped with any other text | H40: NT | I40: NT | J40: NT
B41: Add_Switchboard_TC_35 | C41: PAIRING UI | E41: If user cancel the password alert ,check APP start pairing with device in without router mode. | F41: APP should start pairing procedure with Bluetooth | H41: NT | I41: NT | J41: NT
...

Sheet Issue_Track
